Really interesting that it throws and exception without the try, ain't it?
